[2023-04-15T15:02:15.945+0000] {taskinstance.py:1090} INFO - Dependencies all met for dep_context=non-requeueable deps ti=<TaskInstance: joke_collector.joke_collector_task scheduled__2023-04-14T15:09:00+00:00 [queued]>
[2023-04-15T15:02:15.987+0000] {taskinstance.py:1090} INFO - Dependencies all met for dep_context=requeueable deps ti=<TaskInstance: joke_collector.joke_collector_task scheduled__2023-04-14T15:09:00+00:00 [queued]>
[2023-04-15T15:02:15.989+0000] {taskinstance.py:1288} INFO - 
--------------------------------------------------------------------------------
[2023-04-15T15:02:15.993+0000] {taskinstance.py:1289} INFO - Starting attempt 1 of 2
[2023-04-15T15:02:15.997+0000] {taskinstance.py:1290} INFO - 
--------------------------------------------------------------------------------
[2023-04-15T15:02:16.273+0000] {taskinstance.py:1309} INFO - Executing <Task(PythonVirtualenvOperator): joke_collector_task> on 2023-04-14 15:09:00+00:00
[2023-04-15T15:02:16.291+0000] {standard_task_runner.py:55} INFO - Started process 93 to run task
[2023-04-15T15:02:16.371+0000] {standard_task_runner.py:82} INFO - Running: ['***', 'tasks', 'run', 'joke_collector', 'joke_collector_task', 'scheduled__2023-04-14T15:09:00+00:00', '--job-id', '24', '--raw', '--subdir', 'DAGS_FOLDER/dag_joke_collector.py', '--cfg-path', '/tmp/tmpi0h7fwin']
[2023-04-15T15:02:16.384+0000] {standard_task_runner.py:83} INFO - Job 24: Subtask joke_collector_task
[2023-04-15T15:02:17.047+0000] {task_command.py:389} INFO - Running <TaskInstance: joke_collector.joke_collector_task scheduled__2023-04-14T15:09:00+00:00 [running]> on host 694d4d55fcc1
[2023-04-15T15:02:17.700+0000] {taskinstance.py:1518} INFO - Exporting the following env vars:
AIRFLOW_CTX_DAG_EMAIL=***@example.com
AIRFLOW_CTX_DAG_OWNER=***
AIRFLOW_CTX_DAG_ID=joke_collector
AIRFLOW_CTX_TASK_ID=joke_collector_task
AIRFLOW_CTX_EXECUTION_DATE=2023-04-14T15:09:00+00:00
AIRFLOW_CTX_TRY_NUMBER=1
AIRFLOW_CTX_DAG_RUN_ID=scheduled__2023-04-14T15:09:00+00:00
[2023-04-15T15:02:17.709+0000] {process_utils.py:179} INFO - Executing cmd: /usr/local/bin/python -m virtualenv /tmp/venv7ay9rxhr --system-site-packages
[2023-04-15T15:02:17.974+0000] {process_utils.py:183} INFO - Output:
[2023-04-15T15:06:00.539+0000] {process_utils.py:187} INFO - created virtual environment CPython3.7.16.final.0-64 in 6411ms
[2023-04-15T15:06:00.607+0000] {process_utils.py:187} INFO -   creator CPython3Posix(dest=/tmp/venv7ay9rxhr, clear=False, no_vcs_ignore=False, global=True)
[2023-04-15T15:06:00.616+0000] {process_utils.py:187} INFO -   seeder FromAppData(download=False, pip=bundle, setuptools=bundle, wheel=bundle, via=copy, app_data_dir=/home/***/.local/share/virtualenv)
[2023-04-15T15:06:00.635+0000] {process_utils.py:187} INFO -     added seed packages: pip==23.0.1, setuptools==67.4.0, wheel==0.38.4
[2023-04-15T15:06:00.655+0000] {process_utils.py:187} INFO -   activators BashActivator,CShellActivator,FishActivator,NushellActivator,PowerShellActivator,PythonActivator
[2023-04-15T15:06:01.296+0000] {process_utils.py:179} INFO - Executing cmd: /tmp/venv7ay9rxhr/bin/pip install -r /tmp/venv7ay9rxhr/requirements.txt
[2023-04-15T15:06:01.383+0000] {process_utils.py:183} INFO - Output:
[2023-04-15T15:06:16.787+0000] {process_utils.py:187} INFO - Collecting requests==2.25.1
[2023-04-15T15:06:16.803+0000] {process_utils.py:187} INFO -   Using cached requests-2.25.1-py2.py3-none-any.whl (61 kB)
[2023-04-15T15:06:17.027+0000] {process_utils.py:187} INFO - Requirement already satisfied: chardet<5,>=3.0.2 in /home/***/.local/lib/python3.7/site-packages (from requests==2.25.1->-r /tmp/venv7ay9rxhr/requirements.txt (line 1)) (4.0.0)
[2023-04-15T15:06:17.274+0000] {process_utils.py:187} INFO - Collecting idna<3,>=2.5
[2023-04-15T15:06:17.290+0000] {process_utils.py:187} INFO -   Using cached idna-2.10-py2.py3-none-any.whl (58 kB)
[2023-04-15T15:06:17.319+0000] {process_utils.py:187} INFO - Requirement already satisfied: urllib3<1.27,>=1.21.1 in /home/***/.local/lib/python3.7/site-packages (from requests==2.25.1->-r /tmp/venv7ay9rxhr/requirements.txt (line 1)) (1.26.15)
[2023-04-15T15:06:17.325+0000] {process_utils.py:187} INFO - Requirement already satisfied: certifi>=2017.4.17 in /home/***/.local/lib/python3.7/site-packages (from requests==2.25.1->-r /tmp/venv7ay9rxhr/requirements.txt (line 1)) (2022.12.7)
[2023-04-15T15:06:54.164+0000] {base_job.py:243} ERROR - LocalTaskJob heartbeat got an exception
Traceback (most recent call last):
  File "/home/airflow/.local/lib/python3.7/site-packages/sqlalchemy/engine/base.py", line 3361, in _wrap_pool_connect
    return fn()
  File "/home/airflow/.local/lib/python3.7/site-packages/sqlalchemy/pool/base.py", line 327, in connect
    return _ConnectionFairy._checkout(self)
  File "/home/airflow/.local/lib/python3.7/site-packages/sqlalchemy/pool/base.py", line 894, in _checkout
    fairy = _ConnectionRecord.checkout(pool)
  File "/home/airflow/.local/lib/python3.7/site-packages/sqlalchemy/pool/base.py", line 493, in checkout
    rec = pool._do_get()
  File "/home/airflow/.local/lib/python3.7/site-packages/sqlalchemy/pool/impl.py", line 256, in _do_get
    return self._create_connection()
  File "/home/airflow/.local/lib/python3.7/site-packages/sqlalchemy/pool/base.py", line 273, in _create_connection
    return _ConnectionRecord(self)
  File "/home/airflow/.local/lib/python3.7/site-packages/sqlalchemy/pool/base.py", line 388, in __init__
    self.__connect()
  File "/home/airflow/.local/lib/python3.7/site-packages/sqlalchemy/pool/base.py", line 691, in __connect
    pool.logger.debug("Error on connect(): %s", e)
  File "/home/airflow/.local/lib/python3.7/site-packages/sqlalchemy/util/langhelpers.py", line 72, in __exit__
    with_traceback=exc_tb,
  File "/home/airflow/.local/lib/python3.7/site-packages/sqlalchemy/util/compat.py", line 211, in raise_
    raise exception
  File "/home/airflow/.local/lib/python3.7/site-packages/sqlalchemy/pool/base.py", line 686, in __connect
    self.dbapi_connection = connection = pool._invoke_creator(self)
  File "/home/airflow/.local/lib/python3.7/site-packages/sqlalchemy/engine/create.py", line 574, in connect
    return dialect.connect(*cargs, **cparams)
  File "/home/airflow/.local/lib/python3.7/site-packages/sqlalchemy/engine/default.py", line 598, in connect
    return self.dbapi.connect(*cargs, **cparams)
  File "/home/airflow/.local/lib/python3.7/site-packages/psycopg2/__init__.py", line 122, in connect
    conn = _connect(dsn, connection_factory=connection_factory, **kwasync)
psycopg2.OperationalError: connection to server at "postgres" (172.22.0.3), port 5432 failed: FATAL:  the database system is shutting down


The above exception was the direct cause of the following exception:

Traceback (most recent call last):
  File "/home/airflow/.local/lib/python3.7/site-packages/airflow/jobs/base_job.py", line 215, in heartbeat
    session.merge(self)
  File "/home/airflow/.local/lib/python3.7/site-packages/sqlalchemy/orm/session.py", line 3059, in merge
    _resolve_conflict_map=_resolve_conflict_map,
  File "/home/airflow/.local/lib/python3.7/site-packages/sqlalchemy/orm/session.py", line 3137, in _merge
    options=options,
  File "/home/airflow/.local/lib/python3.7/site-packages/sqlalchemy/orm/session.py", line 2858, in get
    execution_options=execution_options,
  File "/home/airflow/.local/lib/python3.7/site-packages/sqlalchemy/orm/session.py", line 2976, in _get_impl
    load_options=load_options,
  File "/home/airflow/.local/lib/python3.7/site-packages/sqlalchemy/orm/loading.py", line 534, in load_on_pk_identity
    bind_arguments=bind_arguments,
  File "/home/airflow/.local/lib/python3.7/site-packages/sqlalchemy/orm/session.py", line 1713, in execute
    conn = self._connection_for_bind(bind)
  File "/home/airflow/.local/lib/python3.7/site-packages/sqlalchemy/orm/session.py", line 1553, in _connection_for_bind
    engine, execution_options
  File "/home/airflow/.local/lib/python3.7/site-packages/sqlalchemy/orm/session.py", line 747, in _connection_for_bind
    conn = bind.connect()
  File "/home/airflow/.local/lib/python3.7/site-packages/sqlalchemy/engine/base.py", line 3315, in connect
    return self._connection_cls(self, close_with_result=close_with_result)
  File "/home/airflow/.local/lib/python3.7/site-packages/sqlalchemy/engine/base.py", line 96, in __init__
    else engine.raw_connection()
  File "/home/airflow/.local/lib/python3.7/site-packages/sqlalchemy/engine/base.py", line 3394, in raw_connection
    return self._wrap_pool_connect(self.pool.connect, _connection)
  File "/home/airflow/.local/lib/python3.7/site-packages/sqlalchemy/engine/base.py", line 3365, in _wrap_pool_connect
    e, dialect, self
  File "/home/airflow/.local/lib/python3.7/site-packages/sqlalchemy/engine/base.py", line 2199, in _handle_dbapi_exception_noconnection
    sqlalchemy_exception, with_traceback=exc_info[2], from_=e
  File "/home/airflow/.local/lib/python3.7/site-packages/sqlalchemy/util/compat.py", line 211, in raise_
    raise exception
  File "/home/airflow/.local/lib/python3.7/site-packages/sqlalchemy/engine/base.py", line 3361, in _wrap_pool_connect
    return fn()
  File "/home/airflow/.local/lib/python3.7/site-packages/sqlalchemy/pool/base.py", line 327, in connect
    return _ConnectionFairy._checkout(self)
  File "/home/airflow/.local/lib/python3.7/site-packages/sqlalchemy/pool/base.py", line 894, in _checkout
    fairy = _ConnectionRecord.checkout(pool)
  File "/home/airflow/.local/lib/python3.7/site-packages/sqlalchemy/pool/base.py", line 493, in checkout
    rec = pool._do_get()
  File "/home/airflow/.local/lib/python3.7/site-packages/sqlalchemy/pool/impl.py", line 256, in _do_get
    return self._create_connection()
  File "/home/airflow/.local/lib/python3.7/site-packages/sqlalchemy/pool/base.py", line 273, in _create_connection
    return _ConnectionRecord(self)
  File "/home/airflow/.local/lib/python3.7/site-packages/sqlalchemy/pool/base.py", line 388, in __init__
    self.__connect()
  File "/home/airflow/.local/lib/python3.7/site-packages/sqlalchemy/pool/base.py", line 691, in __connect
    pool.logger.debug("Error on connect(): %s", e)
  File "/home/airflow/.local/lib/python3.7/site-packages/sqlalchemy/util/langhelpers.py", line 72, in __exit__
    with_traceback=exc_tb,
  File "/home/airflow/.local/lib/python3.7/site-packages/sqlalchemy/util/compat.py", line 211, in raise_
    raise exception
  File "/home/airflow/.local/lib/python3.7/site-packages/sqlalchemy/pool/base.py", line 686, in __connect
    self.dbapi_connection = connection = pool._invoke_creator(self)
  File "/home/airflow/.local/lib/python3.7/site-packages/sqlalchemy/engine/create.py", line 574, in connect
    return dialect.connect(*cargs, **cparams)
  File "/home/airflow/.local/lib/python3.7/site-packages/sqlalchemy/engine/default.py", line 598, in connect
    return self.dbapi.connect(*cargs, **cparams)
  File "/home/airflow/.local/lib/python3.7/site-packages/psycopg2/__init__.py", line 122, in connect
    conn = _connect(dsn, connection_factory=connection_factory, **kwasync)
sqlalchemy.exc.OperationalError: (psycopg2.OperationalError) connection to server at "postgres" (172.22.0.3), port 5432 failed: FATAL:  the database system is shutting down

(Background on this error at: https://sqlalche.me/e/14/e3q8)
[2023-04-15T15:07:29.421+0000] {process_utils.py:187} INFO - Installing collected packages: idna, requests
[2023-04-15T15:07:29.448+0000] {process_utils.py:187} INFO -   Attempting uninstall: idna
[2023-04-15T15:07:29.455+0000] {process_utils.py:187} INFO -     Found existing installation: idna 3.4
[2023-04-15T15:07:29.489+0000] {process_utils.py:187} INFO -     Not uninstalling idna at /home/***/.local/lib/python3.7/site-packages, outside environment /tmp/venv7ay9rxhr
[2023-04-15T15:07:29.492+0000] {process_utils.py:187} INFO -     Can't uninstall 'idna'. No files were found to uninstall.
[2023-04-15T15:07:30.200+0000] {process_utils.py:187} INFO -   Attempting uninstall: requests
[2023-04-15T15:07:30.240+0000] {process_utils.py:187} INFO -     Found existing installation: requests 2.28.2
[2023-04-15T15:07:30.244+0000] {process_utils.py:187} INFO -     Not uninstalling requests at /home/***/.local/lib/python3.7/site-packages, outside environment /tmp/venv7ay9rxhr
[2023-04-15T15:07:30.247+0000] {process_utils.py:187} INFO -     Can't uninstall 'requests'. No files were found to uninstall.
[2023-04-15T15:07:31.141+0000] {process_utils.py:187} INFO - ERROR: pip's dependency resolver does not currently take into account all the packages that are installed. This behaviour is the source of the following dependency conflicts.
[2023-04-15T15:07:31.151+0000] {process_utils.py:187} INFO - hvac 1.1.0 requires requests<3.0.0,>=2.27.1, but you have requests 2.25.1 which is incompatible.
[2023-04-15T15:07:31.153+0000] {process_utils.py:187} INFO - docker 6.0.1 requires requests>=2.26.0, but you have requests 2.25.1 which is incompatible.
[2023-04-15T15:07:31.155+0000] {process_utils.py:187} INFO - apache-***-providers-http 4.2.0 requires requests>=2.26.0, but you have requests 2.25.1 which is incompatible.
[2023-04-15T15:07:31.156+0000] {process_utils.py:187} INFO - Successfully installed idna-2.10 requests-2.25.1
[2023-04-15T15:07:33.073+0000] {process_utils.py:187} INFO - 
[2023-04-15T15:07:33.074+0000] {process_utils.py:187} INFO - [notice] A new release of pip is available: 23.0.1 -> 23.1
[2023-04-15T15:07:33.083+0000] {process_utils.py:187} INFO - [notice] To update, run: python -m pip install --upgrade pip
